# pytest tests/api/module_a/tests/test_exception_handling.py

import httpx
import pytest

# Define a simple function to create a value
async def create_value():
    value = "temporary_value"
    print(f"Value created: {value}")
    return value

# Define a simple function to remove a value
async def remove_value(value):
    print(f"Value removed: {value}")

# Define a simple function to make a call with the value
# Mocking an API response
@pytest.mark.asyncio
async def make_call_with_value(*args, **kwargs): # Takes any arguments and keyword arguments.
    return httpx.Response( # Returns a mocked httpx.Response object
        status_code=500,
        json={"data": {"id": 1, "first_name": "John", "last_name": "Doe", "email": "john.doe@example.com", "avatar": "https://example.com/avatar.jpg"}}
    )

@pytest.mark.asyncio
async def test_create_and_use_value():
    value = None
    try:
        # Create a value
        value = await create_value()
        
        # Make a call with the created value
        response = await make_call_with_value(value)
        
        # Check if the call was successful
        assert response.status_code == 200
        print("Call succeeded:", response.json())
    
    except Exception as e:
        # Handle any exceptions that occur during the creation or call
        # To trigger this exception, change the value of the status_code to 500
        print("An error occurred:", e)
        raise  # Re-raise the assertion error to fail the test
    
    finally:
        # Remove the created value
        if value is not None:
            await remove_value(value)
        print("Cleanup completed")